2019-04-23 11:44:05,674 ERROR: Exception on /auth/login [POST] [in c:\users\sandra.cabrera\microblog\venv\lib\site-packages\flask\app.py:1761]
Traceback (most recent call last):
  File "c:\users\sandra.cabrera\microblog\venv\lib\site-packages\flask\app.py", line 2292, in wsgi_app
    response = self.full_dispatch_request()
  File "c:\users\sandra.cabrera\microblog\venv\lib\site-packages\flask\app.py", line 1815, in full_dispatch_request
    rv = self.handle_user_exception(e)
  File "c:\users\sandra.cabrera\microblog\venv\lib\site-packages\flask\app.py", line 1718, in handle_user_exception
    reraise(exc_type, exc_value, tb)
  File "c:\users\sandra.cabrera\microblog\venv\lib\site-packages\flask\_compat.py", line 35, in reraise
    raise value
  File "c:\users\sandra.cabrera\microblog\venv\lib\site-packages\flask\app.py", line 1813, in full_dispatch_request
    rv = self.dispatch_request()
  File "c:\users\sandra.cabrera\microblog\venv\lib\site-packages\flask\app.py", line 1799, in dispatch_request
    return self.view_functions[rule.endpoint](**req.view_args)
  File "C:\Users\Sandra.cabrera\microblog\app\auth\routes.py", line 19, in login
    user = User.query.filter_by(username=form.username.data).first()
  File "c:\users\sandra.cabrera\microblog\venv\lib\site-packages\flask_sqlalchemy\__init__.py", line 512, in __get__
    mapper = orm.class_mapper(type)
  File "c:\users\sandra.cabrera\microblog\venv\lib\site-packages\sqlalchemy\orm\base.py", line 441, in class_mapper
    mapper = _inspect_mapped_class(class_, configure=configure)
  File "c:\users\sandra.cabrera\microblog\venv\lib\site-packages\sqlalchemy\orm\base.py", line 420, in _inspect_mapped_class
    mapper._configure_all()
  File "c:\users\sandra.cabrera\microblog\venv\lib\site-packages\sqlalchemy\orm\mapper.py", line 1337, in _configure_all
    configure_mappers()
  File "c:\users\sandra.cabrera\microblog\venv\lib\site-packages\sqlalchemy\orm\mapper.py", line 3229, in configure_mappers
    mapper._post_configure_properties()
  File "c:\users\sandra.cabrera\microblog\venv\lib\site-packages\sqlalchemy\orm\mapper.py", line 1947, in _post_configure_properties
    prop.init()
  File "c:\users\sandra.cabrera\microblog\venv\lib\site-packages\sqlalchemy\orm\interfaces.py", line 196, in init
    self.do_init()
  File "c:\users\sandra.cabrera\microblog\venv\lib\site-packages\sqlalchemy\orm\relationships.py", line 1857, in do_init
    self._generate_backref()
  File "c:\users\sandra.cabrera\microblog\venv\lib\site-packages\sqlalchemy\orm\relationships.py", line 2066, in _generate_backref
    % (backref_key, self, m)
sqlalchemy.exc.ArgumentError: Error creating backref 'author' on relationship 'User.messages_received': property of that name exists on mapper 'mapped class Message->message'
2019-04-23 11:44:10,179 ERROR: Exception on /auth/login [POST] [in c:\users\sandra.cabrera\microblog\venv\lib\site-packages\flask\app.py:1761]
Traceback (most recent call last):
  File "c:\users\sandra.cabrera\microblog\venv\lib\site-packages\flask\app.py", line 2292, in wsgi_app
    response = self.full_dispatch_request()
  File "c:\users\sandra.cabrera\microblog\venv\lib\site-packages\flask\app.py", line 1815, in full_dispatch_request
    rv = self.handle_user_exception(e)
  File "c:\users\sandra.cabrera\microblog\venv\lib\site-packages\flask\app.py", line 1718, in handle_user_exception
    reraise(exc_type, exc_value, tb)
  File "c:\users\sandra.cabrera\microblog\venv\lib\site-packages\flask\_compat.py", line 35, in reraise
    raise value
  File "c:\users\sandra.cabrera\microblog\venv\lib\site-packages\flask\app.py", line 1813, in full_dispatch_request
    rv = self.dispatch_request()
  File "c:\users\sandra.cabrera\microblog\venv\lib\site-packages\flask\app.py", line 1799, in dispatch_request
    return self.view_functions[rule.endpoint](**req.view_args)
  File "C:\Users\Sandra.cabrera\microblog\app\auth\routes.py", line 19, in login
    user = User.query.filter_by(username=form.username.data).first()
  File "c:\users\sandra.cabrera\microblog\venv\lib\site-packages\flask_sqlalchemy\__init__.py", line 512, in __get__
    mapper = orm.class_mapper(type)
  File "c:\users\sandra.cabrera\microblog\venv\lib\site-packages\sqlalchemy\orm\base.py", line 441, in class_mapper
    mapper = _inspect_mapped_class(class_, configure=configure)
  File "c:\users\sandra.cabrera\microblog\venv\lib\site-packages\sqlalchemy\orm\base.py", line 420, in _inspect_mapped_class
    mapper._configure_all()
  File "c:\users\sandra.cabrera\microblog\venv\lib\site-packages\sqlalchemy\orm\mapper.py", line 1337, in _configure_all
    configure_mappers()
  File "c:\users\sandra.cabrera\microblog\venv\lib\site-packages\sqlalchemy\orm\mapper.py", line 3225, in configure_mappers
    raise e
sqlalchemy.exc.InvalidRequestError: One or more mappers failed to initialize - can't proceed with initialization of other mappers. Triggering mapper: 'mapped class User->user'. Original exception was: Error creating backref 'author' on relationship 'User.messages_received': property of that name exists on mapper 'mapped class Message->message'
2019-04-23 11:46:26,893 INFO: Microblog startup [in C:\Users\Sandra.cabrera\microblog\app\__init__.py:74]
2019-04-23 11:49:58,741 INFO: Microblog startup [in C:\Users\Sandra.cabrera\microblog\app\__init__.py:74]
2019-04-23 11:52:27,771 INFO: Microblog startup [in C:\Users\Sandra.cabrera\microblog\app\__init__.py:74]
2019-04-23 11:52:48,560 INFO: Microblog startup [in C:\Users\Sandra.cabrera\microblog\app\__init__.py:74]
2019-04-23 11:53:07,222 INFO: Microblog startup [in C:\Users\Sandra.cabrera\microblog\app\__init__.py:74]
2019-04-23 11:54:04,346 INFO: Microblog startup [in C:\Users\Sandra.cabrera\microblog\app\__init__.py:74]
2019-04-23 11:54:56,139 INFO: Microblog startup [in C:\Users\Sandra.cabrera\microblog\app\__init__.py:74]
2019-04-23 11:57:25,139 INFO: Microblog startup [in C:\Users\Sandra.cabrera\microblog\app\__init__.py:74]
2019-04-23 11:58:36,666 INFO: Microblog startup [in C:\Users\Sandra.cabrera\microblog\app\__init__.py:74]
2019-04-23 11:59:42,089 INFO: Microblog startup [in C:\Users\Sandra.cabrera\microblog\app\__init__.py:74]
2019-04-23 12:01:58,088 INFO: Microblog startup [in C:\Users\Sandra.cabrera\microblog\app\__init__.py:74]
2019-04-23 12:02:07,088 ERROR: Exception on /messages [GET] [in c:\users\sandra.cabrera\microblog\venv\lib\site-packages\flask\app.py:1761]
Traceback (most recent call last):
  File "c:\users\sandra.cabrera\microblog\venv\lib\site-packages\flask\app.py", line 2292, in wsgi_app
    response = self.full_dispatch_request()
  File "c:\users\sandra.cabrera\microblog\venv\lib\site-packages\flask\app.py", line 1815, in full_dispatch_request
    rv = self.handle_user_exception(e)
  File "c:\users\sandra.cabrera\microblog\venv\lib\site-packages\flask\app.py", line 1718, in handle_user_exception
    reraise(exc_type, exc_value, tb)
  File "c:\users\sandra.cabrera\microblog\venv\lib\site-packages\flask\_compat.py", line 35, in reraise
    raise value
  File "c:\users\sandra.cabrera\microblog\venv\lib\site-packages\flask\app.py", line 1813, in full_dispatch_request
    rv = self.dispatch_request()
  File "c:\users\sandra.cabrera\microblog\venv\lib\site-packages\flask\app.py", line 1799, in dispatch_request
    return self.view_functions[rule.endpoint](**req.view_args)
  File "c:\users\sandra.cabrera\microblog\venv\lib\site-packages\flask_login\utils.py", line 261, in decorated_view
    return func(*args, **kwargs)
  File "C:\Users\Sandra.cabrera\microblog\app\main\routes.py", line 157, in messages
    current_user.add_notification('unread_message_count', 0)
  File "c:\users\sandra.cabrera\microblog\venv\lib\site-packages\werkzeug\local.py", line 348, in __getattr__
    return getattr(self._get_current_object(), name)
AttributeError: 'User' object has no attribute 'add_notification'
2019-04-23 12:04:29,311 INFO: Microblog startup [in C:\Users\Sandra.cabrera\microblog\app\__init__.py:74]
2019-04-23 12:04:32,247 ERROR: Exception on /messages [GET] [in c:\users\sandra.cabrera\microblog\venv\lib\site-packages\flask\app.py:1761]
Traceback (most recent call last):
  File "c:\users\sandra.cabrera\microblog\venv\lib\site-packages\flask\app.py", line 2292, in wsgi_app
    response = self.full_dispatch_request()
  File "c:\users\sandra.cabrera\microblog\venv\lib\site-packages\flask\app.py", line 1815, in full_dispatch_request
    rv = self.handle_user_exception(e)
  File "c:\users\sandra.cabrera\microblog\venv\lib\site-packages\flask\app.py", line 1718, in handle_user_exception
    reraise(exc_type, exc_value, tb)
  File "c:\users\sandra.cabrera\microblog\venv\lib\site-packages\flask\_compat.py", line 35, in reraise
    raise value
  File "c:\users\sandra.cabrera\microblog\venv\lib\site-packages\flask\app.py", line 1813, in full_dispatch_request
    rv = self.dispatch_request()
  File "c:\users\sandra.cabrera\microblog\venv\lib\site-packages\flask\app.py", line 1799, in dispatch_request
    return self.view_functions[rule.endpoint](**req.view_args)
  File "c:\users\sandra.cabrera\microblog\venv\lib\site-packages\flask_login\utils.py", line 261, in decorated_view
    return func(*args, **kwargs)
  File "C:\Users\Sandra.cabrera\microblog\app\main\routes.py", line 157, in messages
    current_user.add_notification('unread_message_count', 0)
  File "c:\users\sandra.cabrera\microblog\venv\lib\site-packages\werkzeug\local.py", line 348, in __getattr__
    return getattr(self._get_current_object(), name)
AttributeError: 'User' object has no attribute 'add_notification'
2019-04-23 12:06:55,459 INFO: Microblog startup [in C:\Users\Sandra.cabrera\microblog\app\__init__.py:74]
