2019-04-17 12:35:54,118 ERROR: Exception on /explore [GET] [in c:\users\sandra.cabrera\microblog\venv\lib\site-packages\flask\app.py:1761]
Traceback (most recent call last):
  File "c:\users\sandra.cabrera\microblog\venv\lib\site-packages\flask\app.py", line 2292, in wsgi_app
    response = self.full_dispatch_request()
  File "c:\users\sandra.cabrera\microblog\venv\lib\site-packages\flask\app.py", line 1815, in full_dispatch_request
    rv = self.handle_user_exception(e)
  File "c:\users\sandra.cabrera\microblog\venv\lib\site-packages\flask\app.py", line 1718, in handle_user_exception
    reraise(exc_type, exc_value, tb)
  File "c:\users\sandra.cabrera\microblog\venv\lib\site-packages\flask\_compat.py", line 35, in reraise
    raise value
  File "c:\users\sandra.cabrera\microblog\venv\lib\site-packages\flask\app.py", line 1811, in full_dispatch_request
    rv = self.preprocess_request()
  File "c:\users\sandra.cabrera\microblog\venv\lib\site-packages\flask\app.py", line 2087, in preprocess_request
    rv = func()
  File "C:\Users\Sandra.cabrera\microblog\app\main\routes.py", line 16, in before_request
    if current_user.is_authenticated:
  File "c:\users\sandra.cabrera\microblog\venv\lib\site-packages\werkzeug\local.py", line 348, in __getattr__
    return getattr(self._get_current_object(), name)
  File "c:\users\sandra.cabrera\microblog\venv\lib\site-packages\werkzeug\local.py", line 307, in _get_current_object
    return self.__local()
  File "c:\users\sandra.cabrera\microblog\venv\lib\site-packages\flask_login\utils.py", line 26, in <lambda>
    current_user = LocalProxy(lambda: _get_user())
  File "c:\users\sandra.cabrera\microblog\venv\lib\site-packages\flask_login\utils.py", line 335, in _get_user
    current_app.login_manager._load_user()
  File "c:\users\sandra.cabrera\microblog\venv\lib\site-packages\flask_login\login_manager.py", line 359, in _load_user
    return self.reload_user()
  File "c:\users\sandra.cabrera\microblog\venv\lib\site-packages\flask_login\login_manager.py", line 321, in reload_user
    user = self.user_callback(user_id)
  File "C:\Users\Sandra.cabrera\microblog\app\models.py", line 90, in load_user
    return User.query.get(int(id))
  File "c:\users\sandra.cabrera\microblog\venv\lib\site-packages\flask_sqlalchemy\__init__.py", line 512, in __get__
    mapper = orm.class_mapper(type)
  File "c:\users\sandra.cabrera\microblog\venv\lib\site-packages\sqlalchemy\orm\base.py", line 441, in class_mapper
    mapper = _inspect_mapped_class(class_, configure=configure)
  File "c:\users\sandra.cabrera\microblog\venv\lib\site-packages\sqlalchemy\orm\base.py", line 420, in _inspect_mapped_class
    mapper._configure_all()
  File "c:\users\sandra.cabrera\microblog\venv\lib\site-packages\sqlalchemy\orm\mapper.py", line 1337, in _configure_all
    configure_mappers()
  File "c:\users\sandra.cabrera\microblog\venv\lib\site-packages\sqlalchemy\orm\mapper.py", line 3229, in configure_mappers
    mapper._post_configure_properties()
  File "c:\users\sandra.cabrera\microblog\venv\lib\site-packages\sqlalchemy\orm\mapper.py", line 1947, in _post_configure_properties
    prop.init()
  File "c:\users\sandra.cabrera\microblog\venv\lib\site-packages\sqlalchemy\orm\interfaces.py", line 196, in init
    self.do_init()
  File "c:\users\sandra.cabrera\microblog\venv\lib\site-packages\sqlalchemy\orm\relationships.py", line 1857, in do_init
    self._generate_backref()
  File "c:\users\sandra.cabrera\microblog\venv\lib\site-packages\sqlalchemy\orm\relationships.py", line 2066, in _generate_backref
    % (backref_key, self, m)
sqlalchemy.exc.ArgumentError: Error creating backref 'author' on relationship 'User.messages_received': property of that name exists on mapper 'mapped class Message->message'
2019-04-17 12:41:56,941 ERROR: Exception on /explore [GET] [in c:\users\sandra.cabrera\microblog\venv\lib\site-packages\flask\app.py:1761]
Traceback (most recent call last):
  File "c:\users\sandra.cabrera\microblog\venv\lib\site-packages\flask\app.py", line 2292, in wsgi_app
    response = self.full_dispatch_request()
  File "c:\users\sandra.cabrera\microblog\venv\lib\site-packages\flask\app.py", line 1815, in full_dispatch_request
    rv = self.handle_user_exception(e)
  File "c:\users\sandra.cabrera\microblog\venv\lib\site-packages\flask\app.py", line 1718, in handle_user_exception
    reraise(exc_type, exc_value, tb)
  File "c:\users\sandra.cabrera\microblog\venv\lib\site-packages\flask\_compat.py", line 35, in reraise
    raise value
  File "c:\users\sandra.cabrera\microblog\venv\lib\site-packages\flask\app.py", line 1811, in full_dispatch_request
    rv = self.preprocess_request()
  File "c:\users\sandra.cabrera\microblog\venv\lib\site-packages\flask\app.py", line 2087, in preprocess_request
    rv = func()
  File "C:\Users\Sandra.cabrera\microblog\app\main\routes.py", line 16, in before_request
    if current_user.is_authenticated:
  File "c:\users\sandra.cabrera\microblog\venv\lib\site-packages\werkzeug\local.py", line 348, in __getattr__
    return getattr(self._get_current_object(), name)
  File "c:\users\sandra.cabrera\microblog\venv\lib\site-packages\werkzeug\local.py", line 307, in _get_current_object
    return self.__local()
  File "c:\users\sandra.cabrera\microblog\venv\lib\site-packages\flask_login\utils.py", line 26, in <lambda>
    current_user = LocalProxy(lambda: _get_user())
  File "c:\users\sandra.cabrera\microblog\venv\lib\site-packages\flask_login\utils.py", line 335, in _get_user
    current_app.login_manager._load_user()
  File "c:\users\sandra.cabrera\microblog\venv\lib\site-packages\flask_login\login_manager.py", line 359, in _load_user
    return self.reload_user()
  File "c:\users\sandra.cabrera\microblog\venv\lib\site-packages\flask_login\login_manager.py", line 321, in reload_user
    user = self.user_callback(user_id)
  File "C:\Users\Sandra.cabrera\microblog\app\models.py", line 90, in load_user
    self.password_hash = generate_password_hash(password)
  File "c:\users\sandra.cabrera\microblog\venv\lib\site-packages\flask_sqlalchemy\__init__.py", line 512, in __get__
    mapper = orm.class_mapper(type)
  File "c:\users\sandra.cabrera\microblog\venv\lib\site-packages\sqlalchemy\orm\base.py", line 441, in class_mapper
    mapper = _inspect_mapped_class(class_, configure=configure)
  File "c:\users\sandra.cabrera\microblog\venv\lib\site-packages\sqlalchemy\orm\base.py", line 420, in _inspect_mapped_class
    mapper._configure_all()
  File "c:\users\sandra.cabrera\microblog\venv\lib\site-packages\sqlalchemy\orm\mapper.py", line 1337, in _configure_all
    configure_mappers()
  File "c:\users\sandra.cabrera\microblog\venv\lib\site-packages\sqlalchemy\orm\mapper.py", line 3225, in configure_mappers
    raise e
sqlalchemy.exc.InvalidRequestError: One or more mappers failed to initialize - can't proceed with initialization of other mappers. Triggering mapper: 'mapped class User->user'. Original exception was: Error creating backref 'author' on relationship 'User.messages_received': property of that name exists on mapper 'mapped class Message->message'
2019-04-17 12:42:29,113 INFO: Microblog startup [in C:\Users\Sandra.cabrera\microblog\app\__init__.py:74]
